python3 -m unittest tests/test_users.py
Connection to MySQL database established successfully.
Connection to MySQL database established successfully.
Attempting to insert user: {'username': 'testuser', 'email': 'testuser@example.com', 'password_hash': 'hashed_password'}
An error occurred while creating user: 1062 (23000): Duplicate entry 'testuser@example.com' for key 'users.email'
Connection to MySQL database closed successfully.
FConnection to MySQL database closed successfully.
Connection to MySQL database established successfully.
Connection to MySQL database established successfully.
Attempting to insert user: {'username': 'deleteuser', 'email': 'deleteuser@example.com', 'password_hash': 'hashed_password'}
User created with ID: 18
Connection to MySQL database closed successfully.
Connection to MySQL database established successfully.
Attempting to delete user with ID: 18
Delete user result: Success
Connection to MySQL database closed successfully.
Connection to MySQL database established successfully.
Attempting to read user with ID: 18
Read user: None
Connection to MySQL database closed successfully.
Connection to MySQL database closed successfully.
.Connection to MySQL database established successfully.
Connection to MySQL database established successfully.
Attempting to insert user: {'username': 'readuser', 'email': 'readuser@example.com', 'password_hash': 'hashed_password'}
An error occurred while creating user: 1062 (23000): Duplicate entry 'readuser@example.com' for key 'users.email'
Connection to MySQL database closed successfully.
FConnection to MySQL database closed successfully.
Connection to MySQL database established successfully.
Connection to MySQL database established successfully.
Attempting to insert user: {'username': 'updateuser', 'email': 'updateuser@example.com', 'password_hash': 'hashed_password'}
An error occurred while creating user: 1062 (23000): Duplicate entry 'updateuser@example.com' for key 'users.email'
Connection to MySQL database closed successfully.
FConnection to MySQL database closed successfully.

======================================================================
FAIL: test_create_user (tests.test_users.TestUsersCRUD.test_create_user)
----------------------------------------------------------------------
Traceback (most recent call last):
  File "/home/darth-jade_i/Darth-Star/Courses/ALX/ALX_SWE/ALX_Specialization/The_Darth-Star/server/python_scripts/tests/test_users.py", line 27, in test_create_user
    self.assertIsNotNone(user_id, "Failed to create user: user_id is None")
AssertionError: unexpectedly None : Failed to create user: user_id is None

======================================================================
FAIL: test_read_user (tests.test_users.TestUsersCRUD.test_read_user)
----------------------------------------------------------------------
Traceback (most recent call last):
  File "/home/darth-jade_i/Darth-Star/Courses/ALX/ALX_SWE/ALX_Specialization/The_Darth-Star/server/python_scripts/tests/test_users.py", line 43, in test_read_user
    self.assertIsNotNone(user_id, "Failed to create user for read test")
AssertionError: unexpectedly None : Failed to create user for read test

======================================================================
FAIL: test_update_user (tests.test_users.TestUsersCRUD.test_update_user)
----------------------------------------------------------------------
Traceback (most recent call last):
  File "/home/darth-jade_i/Darth-Star/Courses/ALX/ALX_SWE/ALX_Specialization/The_Darth-Star/server/python_scripts/tests/test_users.py", line 58, in test_update_user
    self.assertIsNotNone(user_id, "Failed to create user for update test")
AssertionError: unexpectedly None : Failed to create user for update test

----------------------------------------------------------------------
Ran 4 tests in 2.571s
